Workbook

Sheet Net Worth Summary
A1: NET WORTH REPORT
A2: VIPULBHAI LALJIBHAI PATEL
A3: As on | B3: 10/09/2026 | C3: Currency | D3: INR (₹) — Indian Rupees
A4: Prepared from | B4: Vipulbhai BALANCESHEET_1-23102026161349.PDF (2 pages, 84 account lines)
A5: Balance Sheet total on both sides: ₹ 7,39,01,963.50 | All amounts are book values as per the source, not market valuations.
A6: Jump to: | B6: Calculation | C6: Assets Detail | D6: Liabilities Detail | E6: Source B/S | F6: Notes & Method
A8: HEADLINE FIGURES
A9: Particulars | B9: Amount (₹) | C9: % of Assets | D9: Basis
A10: Total Assets | B10: ='Assets Detail'!D53 -> 73901964 | C10: =B10/$B$10 -> 1 | D10: Asset side of the Balance Sheet
A11: Total External Liabilities | B11: ='Liabilities Detail'!E42 -> 60851626 | C11: =B11/$B$10 -> 0.82341014 | D11: Liabilities side, excluding equity
A12: NET WORTH (Assets − Liabilities) | B12: =B10-B11 -> 13050337 | C12: =B12/$B$10 -> 0.17658986 | D12: Owner's equity
A13: Check: Assets − Liabilities − Net Worth | B13: =B10-B11-B12 -> 0 | D13: Must be 0.00
A15: ASSET MIX BY CATEGORY
A16: Asset Category | B16: Amount (₹) | C16: % of Assets | D16: No. of Accounts
A17: Land & Property | B17: =SUMIF('Assets Detail'!$A$5:$A$52,A17,'Assets Detail'!$D$5:$D$52) -> 16681593 | C17: =B17/$B$10 -> 0.22572598 | D17: =COUNTIF('Assets Detail'!$A$5:$A$52,A17) -> 8
A18: Gold & Valuables | B18: =SUMIF('Assets Detail'!$A$5:$A$52,A18,'Assets Detail'!$D$5:$D$52) -> 8788 | C18: =B18/$B$10 -> 0.0001189143 | D18: =COUNTIF('Assets Detail'!$A$5:$A$52,A18) -> 1
A19: Vehicles | B19: =SUMIF('Assets Detail'!$A$5:$A$52,A19,'Assets Detail'!$D$5:$D$52) -> 330355.87 | C19: =B19/$B$10 -> 0.0044701907 | D19: =COUNTIF('Assets Detail'!$A$5:$A$52,A19) -> 1
A20: Investments (MF, Shares, Trading) | B20: =SUMIF('Assets Detail'!$A$5:$A$52,A20,'Assets Detail'!$D$5:$D$52) -> 6688140.2 | C20: =B20/$B$10 -> 0.090500169 | D20: =COUNTIF('Assets Detail'!$A$5:$A$52,A20) -> 15
A21: Deposits & Fixed Deposits | B21: =SUMIF('Assets Detail'!$A$5:$A$52,A21,'Assets Detail'!$D$5:$D$52) -> 218608.52 | C21: =B21/$B$10 -> 0.0029580881 | D21: =COUNTIF('Assets Detail'!$A$5:$A$52,A21) -> 4
A22: Loans & Advances Given | B22: =SUMIF('Assets Detail'!$A$5:$A$52,A22,'Assets Detail'!$D$5:$D$52) -> 47878472 | C22: =B22/$B$10 -> 0.64786468 | D22: =COUNTIF('Assets Detail'!$A$5:$A$52,A22) -> 11
A23: Receivables & Tax Recoverable | B23: =SUMIF('Assets Detail'!$A$5:$A$52,A23,'Assets Detail'!$D$5:$D$52) -> 377938 | C23: =B23/$B$10 -> 0.0051140454 | D23: =COUNTIF('Assets Detail'!$A$5:$A$52,A23) -> 3
A24: Cash & Bank Balances | B24: =SUMIF('Assets Detail'!$A$5:$A$52,A24,'Assets Detail'!$D$5:$D$52) -> 1718067.9 | C24: =B24/$B$10 -> 0.023247933 | D24: =COUNTIF('Assets Detail'!$A$5:$A$52,A24) -> 5
A25: TOTAL ASSETS | B25: =SUM(B17:B24) -> 73901964 | C25: =B25/$B$10 -> 1 | D25: =SUM(D17:D24) -> 48
A27: LIABILITY MIX BY CATEGORY
A28: Liability Category | B28: Amount (₹) | C28: % of Assets | D28: No. of Accounts
A29: Secured Loans (Housing) | B29: =SUMIF('Liabilities Detail'!$B$5:$B$40,A29,'Liabilities Detail'!$E$5:$E$40) -> 755798.5 | C29: =B29/$B$10 -> 0.010227042 | D29: =COUNTIF('Liabilities Detail'!$B$5:$B$40,A29) -> 1
A30: Unsecured Loans & Borrowings | B30: =SUMIF('Liabilities Detail'!$B$5:$B$40,A30,'Liabilities Detail'!$E$5:$E$40) -> 56498432 | C30: =B30/$B$10 -> 0.76450515 | D30: =COUNTIF('Liabilities Detail'!$B$5:$B$40,A30) -> 16
A31: Trade Creditors & Payables | B31: =SUMIF('Liabilities Detail'!$B$5:$B$40,A31,'Liabilities Detail'!$E$5:$E$40) -> 1898699 | C31: =B31/$B$10 -> 0.025692132 | D31: =COUNTIF('Liabilities Detail'!$B$5:$B$40,A31) -> 6
A32: Current Liabilities | B32: =SUMIF('Liabilities Detail'!$B$5:$B$40,A32,'Liabilities Detail'!$E$5:$E$40) -> 265500 | C32: =B32/$B$10 -> 0.0035925974 | D32: =COUNTIF('Liabilities Detail'!$B$5:$B$40,A32) -> 4
A33: Credit Card Dues | B33: =SUMIF('Liabilities Detail'!$B$5:$B$40,A33,'Liabilities Detail'!$E$5:$E$40) -> 11734.37 | C33: =B33/$B$10 -> 0.0001587829 | D33: =COUNTIF('Liabilities Detail'!$B$5:$B$40,A33) -> 2
A34: Other Credit / Contra Balances | B34: =SUMIF('Liabilities Detail'!$B$5:$B$40,A34,'Liabilities Detail'!$E$5:$E$40) -> 1421462.8 | C34: =B34/$B$10 -> 0.019234439 | D34: =COUNTIF('Liabilities Detail'!$B$5:$B$40,A34) -> 4
A35: TOTAL EXTERNAL LIABILITIES | B35: =SUM(B29:B34) -> 60851626 | C35: =B35/$B$10 -> 0.82341014 | D35: =SUM(D29:D34) -> 33
A37: NET WORTH COMPOSITION (equity accounts on the Liabilities side)
A38: Equity Component | B38: Amount (₹) | C38: % of Net Worth | D38: Source Group
A39: Owner's Capital | B39: =SUMIF('Liabilities Detail'!$B$5:$B$40,A39,'Liabilities Detail'!$E$5:$E$40) -> 12453087 | C39: =B39/$B$12 -> 0.95423484 | D39: CAPITAL A/C
A40: Reserves & Surplus | B40: =SUMIF('Liabilities Detail'!$B$5:$B$40,A40,'Liabilities Detail'!$E$5:$E$40) -> 174850.8 | C40: =B40/$B$12 -> 0.013398182 | D40: CAPITAL RESERVE AND SURPLUS A/C
A41: Unappropriated Income | B41: =SUMIF('Liabilities Detail'!$B$5:$B$40,A41,'Liabilities Detail'!$E$5:$E$40) -> 422400 | C41: =B41/$B$12 -> 0.032366979 | D41: INCOME A/C
A42: TOTAL EQUITY = NET WORTH | B42: =SUM(B39:B41) -> 13050337 | C42: =B42/$B$12 -> 1
A43: Check: Equity − Net Worth (must be 0.00) | B43: =B42-B12 -> 0
A45: KEY RATIOS
...

Sheet Net Worth Calculation
A1: NET WORTH — CALCULATION & RECONCILIATION
A2: VIPULBHAI LALJIBHAI PATEL | As on 10/09/2026 | Amounts in INR (₹)
A4: STEP 1 — TOTAL ASSETS
A5: Total Assets (asset side of the Balance Sheet) | B5: ='Net Worth Summary'!B10 -> 73901964 | C5: Links to 'Assets Detail' total.
A7: STEP 2 — TOTAL EXTERNAL LIABILITIES
A8: Liability Category | B8: Amount (₹) | C8: Basis
A9: Secured Loans (Housing) | B9: ='Net Worth Summary'!B29 -> 755798.5 | C9: From 'Net Worth Summary' → Liability Mix
A10: Unsecured Loans & Borrowings | B10: ='Net Worth Summary'!B30 -> 56498432 | C10: From 'Net Worth Summary' → Liability Mix
A11: Trade Creditors & Payables | B11: ='Net Worth Summary'!B31 -> 1898699 | C11: From 'Net Worth Summary' → Liability Mix
A12: Current Liabilities | B12: ='Net Worth Summary'!B32 -> 265500 | C12: From 'Net Worth Summary' → Liability Mix
A13: Credit Card Dues | B13: ='Net Worth Summary'!B33 -> 11734.37 | C13: From 'Net Worth Summary' → Liability Mix
A14: Other Credit / Contra Balances | B14: ='Net Worth Summary'!B34 -> 1421462.8 | C14: From 'Net Worth Summary' → Liability Mix
A15: TOTAL EXTERNAL LIABILITIES | B15: =SUM(B9:B14) -> 60851626
A17: STEP 3 — NET WORTH
A18: NET WORTH = Total Assets − External Liabilities | B18: =B5-B15 -> 13050337 | C18: Owner's stake in the business / personal balance sheet.
A20: STEP 4 — RECONCILIATION WITH THE EQUITY ACCOUNTS IN THE BALANCE SHEET
A21: Equity Account | B21: Amount (₹) | C21: Source Group
A22: Owner's Capital | B22: ='Net Worth Summary'!B39 -> 12453087 | C22: CAPITAL A/C
A23: Reserves & Surplus | B23: ='Net Worth Summary'!B40 -> 174850.8 | C23: CAPITAL RESERVE AND SURPLUS A/C
A24: Unappropriated Income | B24: ='Net Worth Summary'!B41 -> 422400 | C24: INCOME A/C
A25: Equity per Balance Sheet | B25: =SUM(B22:B24) -> 13050337
A26: Difference: Net Worth − Equity (must be 0.00) | B26: =B18-B25 -> 0
A28: MEMO ITEMS & CROSS-CHECKS
A29: Book capital (Capital + Reserves only, before untransferred income) | B29: =B22+B23 -> 12627937
A30: Net profit transferred from P&L (included in Reserves & Surplus) | B30: ='Net Worth Summary'!B40 -> 174850.8
A31: Income A/C not yet transferred to P&L (Salary Income) | B31: =B24 -> 422400
A32: Balance Sheet grand total — Liabilities side | B32: ='Balance Sheet (Source)'!B61 -> 73901964
A33: Balance Sheet grand total — Assets side | B33: ='Balance Sheet (Source)'!D61 -> 73901964
A34: Check: Total Assets − B/S grand total (must be 0.00) | B34: =B5-B32 -> 0
A35: Check: External Liabilities + Equity − B/S total (must be 0.00) | B35: =B15+B25-B32 -> 0
A38: METHOD
A39: • Total Assets = all balances reported on the Assets (right) side of the source Balance Sheet.
A40: • External Liabilities = every balance on the Liabilities (left) side except the three equity accounts.
A41: • Net Worth = Total Assets − External Liabilities, cross-checked against Capital + Reserves + Income.
A42: • Because the source Balance Sheet balances, the two computations agree exactly (see difference rows above).

Sheet Assets Detail
A1: ASSETS — DETAILED SCHEDULE
A2: VIPULBHAI LALJIBHAI PATEL | As on 10/09/2026 | Amounts in INR (₹) | Source: Assets side of the Balance Sheet
A4: Asset Category | B4: Source Group (B/S) | C4: Account / Particulars | D4: Amount (₹) | E4: % of Total Assets | F4: Source Page
A5: Land & Property | B5: ASSETS A/C | C5: AGRI. LAND PURCHASE(ASTGAM-801)1/4 A/C | D5: 198825 | E5: =D5/$D$53 -> 0.0026903886 | F5: 1
A6: Land & Property | B6: ASSETS A/C | C6: AGRI. LAND PURCHASE(ASTGAM-827)1/4 A/C | D6: 278250 | E6: =D6/$D$53 -> 0.0037651232 | F6: 1
A7: Land & Property | B7: ASSETS A/C | C7: AGRI. LAND PURCHASE(ASTGAM-830)1/4 A/C | D7: 662125 | E7: =D7/$D$53 -> 0.0089595048 | F7: 1
A8: Land & Property | B8: ASSETS A/C | C8: AGRI. LAND PURCHASE(BAMANIYA-179/1)1/2 A/C | D8: 404000 | E8: =D8/$D$53 -> 0.0054667018 | F8: 1
A9: Land & Property | B9: ASSETS A/C | C9: LAND PLOT NO 43- LAKEVIEW RESIDENCY A/C | D9: 134150 | E9: =D9/$D$53 -> 0.0018152427 | F9: 1
A10: Land & Property | B10: ASSETS A/C | C10: LAND-PLOT NO.- SACHIN PURCHASE A/C | D10: 6960455.9 | E10: =D10/$D$53 -> 0.094184993 | F10: 1
A11: Land & Property | B11: ASSETS A/C | C11: RESI.PROPERTY CONSTRUCTION | D11: 7696700 | E11: =D11/$D$53 -> 0.10414744 | F11: 1
A12: Land & Property | B12: ASSETS A/C | C12: RESI.PROPERTY SUMANGAL | D12: 347087 | E12: =D12/$D$53 -> 0.004696587 | F12: 1
A13: Gold & Valuables | B13: ASSETS A/C | C13: GOLD ORNAMENTS | D13: 8788 | E13: =D13/$D$53 -> 0.0001189143 | F13: 1
A14: Vehicles | B14: ASSETS A/C | C14: AKSHAR AUTO ELECTRIC | D14: 330355.87 | E14: =D14/$D$53 -> 0.0044701907 | F14: 1
A15: Investments (MF, Shares, Trading) | B15: INVESTMENT A/C | C15: BARODA PIONEER M FUND-15034352 | D15: 72000 | E15: =D15/$D$53 -> 0.0009742637 | F15: 1
A16: Investments (MF, Shares, Trading) | B16: INVESTMENT A/C | C16: DIESEL WORLD E SHARE | D16: 23000 | E16: =D16/$D$53 -> 0.0003112231 | F16: 1
... A52: Cash & Bank Balances | B52: BANK BOOK A/C | C52: ICICI BANK(YOG V PATEL-SB-777701057255)A/C | D52: 200354 | E52: =D52/$D$53 -> 0.0027110782 | F52: 2
A53: TOTAL ASSETS | D53: =SUM(D5:D52) -> 73901964 | E53: =SUM(E5:E52) -> 1
A55: RECONCILIATION TO THE SOURCE BALANCE SHEET GROUPS
A56: Source Group | B56: Group Total (PDF) | C56: Sum of Lines (above) | D56: Difference | E56: Accounts | F56: Page(s)
A57: ASSETS A/C | B57: 17075737 | C57: =SUMIF($B$5:$B$52,A57,$D$5:$D$52) -> 17075737 | D57: =C57-B57 -> 0 | E57: 12 | F57: 1
A58: INVESTMENT A/C | B58: 6742939.2 | C58: =SUMIF($B$5:$B$52,A58,$D$5:$D$52) -> 6742939.2 | D58: =C58-B58 -> 0 | E58: 16 | F58: 1
A59: LOAN & ADVANCES A/C | B59: 47828472 | C59: =SUMIF($B$5:$B$52,A59,$D$5:$D$52) -> 47828472 | D59: =C59-B59 -> 0 | E59: 10 | F59: 1, 2
A60: SUNDRY DEBTORS/CREDITORS A/C | B60: 176938 | C60: =SUMIF($B$5:$B$52,A60,$D$5:$D$52) -> 176938 | D60: =C60-B60 -> 0 | E60: 1 | F60: 2
A61: DEPOSIT A/C | B61: 108809.52 | C61: =SUMIF($B$5:$B$52,A61,$D$5:$D$52) -> 108809.52 | D61: =C61-B61 -> 0 | E61: 1 | F61: 2
A62: BANK BOOK A/C | B62: 1718067.9 | C62: =SUMIF($B$5:$B$52,A62,$D$5:$D$52) -> 1718067.9 | D62: =C62-B62 -> 0 | E62: 5 | F62: 2
A63: UN-SECURED LOAN A/C | B63: 50000 | C63: =SUMIF($B$5:$B$52,A63,$D$5:$D$52) -> 50000 | D63: =C63-B63 -> 0 | E63: 1 | F63: 2
A64: PROVISION A/C | B64: 201000 | C64: =SUMIF($B$5:$B$52,A64,$D$5:$D$52) -> 201000 | D64: =C64-B64 -> 0 | E64: 2 | F64: 2

Sheet Liabilities Detail
A1: LIABILITIES & EQUITY — DETAILED SCHEDULE
A2: VIPULBHAI LALJIBHAI PATEL | As on 10/09/2026 | Amounts in INR (₹) | Source: Liabilities side of the Balance Sheet
A4: Classification | B4: Category | C4: Source Group (B/S) | D4: Account / Particulars | E4: Amount (₹) | F4: Source Page
A5: External Liability | B5: Secured Loans (Housing) | C5: SECURED LOAN A/C | D5: BOB HOUSIONG LOAN | E5: 755798.5 | F5: 1
A6: External Liability | B6: Unsecured Loans & Borrowings | C6: LOAN & ADVANCES A/C | D6: AKSHAR DIESELS-NAVSARI | E6: 6855754 | F6: 1
A7: External Liability | B7: Unsecured Loans & Borrowings | C7: LOAN & ADVANCES A/C | D7: ANAND JESWANI/ANAND HARI GOVIND | E7: 10500000 | F7: 1
A8: External Liability | B8: Unsecured Loans & Borrowings | C8: LOAN & ADVANCES A/C | D8: BABU BAVANAJI KANARA | E8: 100000 | F8: 1
A9: External Liability | B9: Unsecured Loans & Borrowings | C9: LOAN & ADVANCES A/C | D9: JALPABEN VIPULBHAI PATEL | E9: 4537126.5 | F9: 1
A10: External Liability | B10: Unsecured Loans & Borrowings | C10: LOAN & ADVANCES A/C | D10: LALJIBHAI G KHATRA | E10: 9724517 | F10: 1
A11: External Liability | B11: Unsecured Loans & Borrowings | C11: LOAN & ADVANCES A/C | D11: PARESHBHAI MAVJIBHAI PATEL | E11: 5000000 | F11: 1
A12: External Liability | B12: Unsecured Loans & Borrowings | C12: LOAN & ADVANCES A/C | D12: RAMANIKBHAI GOBARBHAI THUMMAR | E12: 3000000 | F12: 1
A13: External Liability | B13: Unsecured Loans & Borrowings | C13: LOAN & ADVANCES A/C | D13: RAMNIKLAL RANCHHODBHAI RANK | E13: 1928000 | F13: 1
A14: External Liability | B14: Unsecured Loans & Borrowings | C14: LOAN & ADVANCES A/C | D14: SHREE SHALU MOTORS | E14: 2500000 | F14: 1
A15: External Liability | B15: Unsecured Loans & Borrowings | C15: LOAN & ADVANCES A/C | D15: TRUSHAR DHARMESHBHAI SORATHIYA | E15: 10000000 | F15: 1
A16: External Liability | B16: Unsecured Loans & Borrowings | C16: UN-SECURED LOAN A/C | D16: ASHIRWAD FABRICS | E16: 500000 | F16: 1
... A40: Equity | B40: Unappropriated Income | C40: INCOME A/C | D40: SALARY INCOME A/C | E40: 422400 | F40: 2
A41: TOTAL — LIABILITIES SIDE (as per Balance Sheet) | E41: =SUM(E5:E40) -> 73901964
A42: of which: EXTERNAL LIABILITIES (deducted from assets) | E42: =SUMIF($A$5:$A$40,"External Liability",$E$5:$E$40) -> 60851626
A43: of which: EQUITY / NET WORTH (capital, reserves, income) | E43: =SUMIF($A$5:$A$40,"Equity",$E$5:$E$40) -> 13050337
A44: Check: Total − External − Equity (must be 0.00) | E44: =E41-E42-E43 -> 0
A46: RECONCILIATION TO THE SOURCE BALANCE SHEET GROUPS
A47: Source Group | B47: Group Total (PDF) | C47: Sum of Lines (above) | D47: Difference | E47: Accounts | F47: Page(s)
A48: EXPENSE(CAPITAL)A/C | B48: 11734.37 | C48: =SUMIF($C$5:$C$40,A48,$E$5:$E$40) -> 11734.37 | D48: =C48-B48 -> 0 | E48: 2 | F48: 1
A49: ASSETS A/C | B49: 150000 | C49: =SUMIF($C$5:$C$40,A49,$E$5:$E$40) -> 150000 | D49: =C49-B49 -> 0 | E49: 1 | F49: 1
A50: CAPITAL RESERVE AND SURPLUS A/C | B50: 174850.8 | C50: =SUMIF($C$5:$C$40,A50,$E$5:$E$40) -> 174850.8 | D50: =C50-B50 -> 0 | E50: 1 | F50: 1
A51: INVESTMENT A/C | B51: 28.54 | C51: =SUMIF($C$5:$C$40,A51,$E$5:$E$40) -> 28.54 | D51: =C51-B51 -> 0 | E51: 1 | F51: 1
A52: LOAN & ADVANCES A/C | B52: 54145398 | C52: =SUMIF($C$5:$C$40,A52,$E$5:$E$40) -> 54145398 | D52: =C52-B52 -> 0 | E52: 10 | F52: 1
A53: SUNDRY DEBTORS/CREDITORS A/C | B53: 397949.07 | C53: =SUMIF($C$5:$C$40,A53,$E$5:$E$40) -> 397949.07 | D53: =C53-B53 -> 0 | E53: 1 | F53: 1
A54: CASH BOOK A/C | B54: 873485.19 | C54: =SUMIF($C$5:$C$40,A54,$E$5:$E$40) -> 873485.19 | D54: =C54-B54 -> 0 | E54: 1 | F54: 1
A55: CAPITAL A/C | B55: 12453087 | C55: =SUMIF($C$5:$C$40,A55,$E$5:$E$40) -> 12453087 | D55: =C55-B55 -> 0 | E55: 1 | F55: 1
A56: SECURED LOAN A/C | B56: 755798.5 | C56: =SUMIF($C$5:$C$40,A56,$E$5:$E$40) -> 755798.5 | D56: =C56-B56 -> 0 | E56: 1 | F56: 1
A57: UN-SECURED LOAN A/C | B57: 2353034 | C57: =SUMIF($C$5:$C$40,A57,$E$5:$E$40) -> 2353034 | D57: =C57-B57 -> 0 | E57: 6 | F57: 1
A58: SUNDRY CREDITORS/DEBTORS A/C | B58: 1898699 | C58: =SUMIF($C$5:$C$40,A58,$E$5:$E$40) -> 1898699 | D58: =C58-B58 -> 0 | E58: 6 | F58: 1
A59: CURRENT LIABILITIES A/C | B59: 265500 | C59: =SUMIF($C$5:$C$40,A59,$E$5:$E$40) -> 265500 | D59: =C59-B59 -> 0 | E59: 4 | F59: 2
A60: INCOME A/C | B60: 422400 | C60: =SUMIF($C$5:$C$40,A60,$E$5:$E$40) -> 422400 | D60: =C60-B60 -> 0 | E60: 1 | F60: 2

Sheet Balance Sheet (Source)
A1: BALANCE SHEET — FAITHFUL TRANSCRIPT OF THE SOURCE PDF
A2: VIPULBHAI LALJIBHAI PATEL | BALANCE SHEET AS ON : 10/09/2026 | Source: Vipulbhai BALANCESHEET_1-23102026161349.PDF | Account names reproduced as printed (typos included)
A4: LIABILITIES — Name of the Accounts | B4: Amount (₹) | C4: ASSETS — Name of the Accounts | D4: Amount (₹)
A5: EXPENSE(CAPITAL)A/C | B5: 11734.37 | C5: ASSETS A/C | D5: 17075737
A6: CREDIT CARD EXP (HDFC)-3988 A/C | B6: 0.37 | C6: AGRI. LAND PURCHASE(ASTGAM-801)1/4 A/C | D6: 198825
A7: CREDIT CARD EXP (ICICI)-4005 A/C | B7: 11734 | C7: AGRI. LAND PURCHASE(ASTGAM-827)1/4 A/C | D7: 278250
A8: ASSETS A/C | B8: 150000 | C8: AGRI. LAND PURCHASE(ASTGAM-830)1/4 A/C | D8: 662125
A9: LAND-PLOT NO.- SISODRA SALES A/C | B9: 150000 | C9: AGRI. LAND PURCHASE(BAMANIYA-179/1)1/2 A/C | D9: 404000
A10: CAPITAL RESERVE AND SURPLUS A/C | B10: 174850.8 | C10: AKSHAR AUTO ELECTRIC | D10: 330355.87
A11: NET PROFIT XFER FROM P/L A/C | B11: 174850.8 | C11: GOLD ORNAMENTS | D11: 8788
A12: INVESTMENT A/C | B12: 28.54 | C12: GSPC GAS | D12: 5000
A13: ZERODHA BROKING LIMITED NSE | B13: 28.54 | C13: LAND PLOT NO 43- LAKEVIEW RESIDENCY A/C | D13: 134150
A14: LOAN & ADVANCES A/C | B14: 54145398 | C14: LAND-PLOT NO.- SACHIN PURCHASE A/C | D14: 6960455.9
A15: AKSHAR DIESELS-NAVSARI | B15: 6855754 | C15: RESI.PROPERTY CONSTRUCTION | D15: 7696700
A16: ANAND JESWANI/ANAND HARI GOVIND | B16: 10500000 | C16: RESI.PROPERTY SUMANGAL | D16: 347087
... A53: SALARY INCOME A/C | B53: 422400 | C53: ICICI BANK SB-704801500015 (LO) | D53: 17415
C54: ICICI BANK SB-777701047155 | D54: 1406146
C55: ICICI BANK(YOG V PATEL-SB-777701057255)A/C | D55: 200354
C56: UN-SECURED LOAN A/C | D56: 50000
C57: TECHNO | D57: 50000
C58: PROVISION A/C | D58: 201000
C59: PROFESSIONAL TAX A/C | D59: 1000
C60: T.D.S. A/C | D60: 200000
A61: T O T A L : | B61: 73901964 | C61: T O T A L : | D61: 73901964
A62: Sum of group totals (recomputed) | B62: =B5+B8+B10+B12+B14+B25+B27+B29+B31+B33+B40+B47+B52 -> 73901964 | C62: Sum of group totals (recomputed) | D62: =D5+D18+D35+D46+D48+D50+D56+D58 -> 73901964
A63: Difference vs printed total (must be 0.00) | B63: =B62-B61 -> 0 | C63: Difference vs printed total (must be 0.00) | D63: =D62-D61 -> 0
A65: FULL GROUP-BY-GROUP VALIDATION (printed total vs sum of account lines)
A66: Side | B66: Group / Account Head | C66: Printed Group Total | D66: Sum of Account Lines | E66: Difference | F66: Page(s)
A67: Liabilities | B67: EXPENSE(CAPITAL)A/C | C67: 11734.37 | D67: 11734.37 | E67: 0 | F67: 1
A68: Liabilities | B68: ASSETS A/C | C68: 150000 | D68: 150000 | E68: 0 | F68: 1
A69: Liabilities | B69: CAPITAL RESERVE AND SURPLUS A/C | C69: 174850.8 | D69: 174850.8 | E69: 0 | F69: 1
A70: Liabilities | B70: INVESTMENT A/C | C70: 28.54 | D70: 28.54 | E70: 0 | F70: 1
A71: Liabilities | B71: LOAN & ADVANCES A/C | C71: 54145398 | D71: 54145398 | E71: 0 | F71: 1
A72: Liabilities | B72: SUNDRY DEBTORS/CREDITORS A/C | C72: 397949.07 | D72: 397949.07 | E72: 0 | F72: 1
A73: Liabilities | B73: CASH BOOK A/C | C73: 873485.19 | D73: 873485.19 | E73: 0 | F73: 1
A74: Liabilities | B74: CAPITAL A/C | C74: 12453087 | D74: 12453087 | E74: 0 | F74: 1
A75: Liabilities | B75: SECURED LOAN A/C | C75: 755798.5 | D75: 755798.5 | E75: 0 | F75: 1
A76: Liabilities | B76: UN-SECURED LOAN A/C | C76: 2353034 | D76: 2353034 | E76: 0 | F76: 1
A77: Liabilities | B77: SUNDRY CREDITORS/DEBTORS A/C | C77: 1898699 | D77: 1898699 | E77: 0 | F77: 1
A78: Assets | B78: ASSETS A/C | C78: 17075737 | D78: 17075737 | E78: 0 | F78: 1
...

Sheet Notes & Method
A1: NOTES, METHOD & DATA QUALITY
A2: Net Worth Report — VIPULBHAI LALJIBHAI PATEL — as on 10/09/2026
A4: 1. PURPOSE & DEFINITION
A5: This workbook converts the two-page Balance Sheet PDF into an Excel net worth statement with detailed schedules.
A6: Net Worth = Total Assets − Total External Liabilities. It is cross-checked against the owner's equity accounts.
A7: Result: Total Assets ₹ 7,39,01,963.50 − External Liabilities ₹ 6,08,51,626.18 = Net Worth ₹ 1,30,50,337.32.
A9: 2. SOURCE DATA
A10: Source file: Vipulbhai BALANCESHEET_1-23102026161349.PDF — 'BALANCE SHEET AS ON : 10/09/2026' for VIPULBHAI LALJIBHAI PATEL (Oracle Reports PDF, 2 pages).
A11: Printed grand total: Liabilities ₹ 7,39,01,963.50 / Assets ₹ 7,39,01,963.50 (both sides agree).
A12: Parsed: 21 account groups, 84 account lines. All amounts are in INR (₹).
A13: Account names, spellings and abbreviations are reproduced exactly as printed in the source.
A15: 3. CLASSIFICATION RULES
... A67: Notes & Method
